2018-02-17 00:54:13,020 ERROR: Exception on /login [GET] 
 		 [in /home/hadoop/development_projects/python/flask_microblog/virtenv/lib/python3.5/site-packages/flask/app.py:1560]
Traceback (most recent call last):
  File "/home/hadoop/development_projects/python/flask_microblog/virtenv/lib/python3.5/site-packages/flask/app.py", line 1982, in wsgi_app
  File "/home/hadoop/development_projects/python/flask_microblog/virtenv/lib/python3.5/site-packages/flask/app.py", line 1614, in full_dispatch_request
  File "/home/hadoop/development_projects/python/flask_microblog/virtenv/lib/python3.5/site-packages/flask/app.py", line 1517, in handle_user_exception
  File "/home/hadoop/development_projects/python/flask_microblog/virtenv/lib/python3.5/site-packages/flask/_compat.py", line 33, in reraise
  File "/home/hadoop/development_projects/python/flask_microblog/virtenv/lib/python3.5/site-packages/flask/app.py", line 1612, in full_dispatch_request
  File "/home/hadoop/development_projects/python/flask_microblog/virtenv/lib/python3.5/site-packages/flask/app.py", line 1598, in dispatch_request
  File "/home/hadoop/development_projects/python/flask_microblog/app/routes.py", line 40, in login
    form_obj = LoginForm()
  File "/home/hadoop/development_projects/python/flask_microblog/virtenv/lib/python3.5/site-packages/wtforms/form.py", line 212, in __call__
  File "/home/hadoop/development_projects/python/flask_microblog/virtenv/lib/python3.5/site-packages/flask_wtf/form.py", line 88, in __init__
  File "/home/hadoop/development_projects/python/flask_microblog/virtenv/lib/python3.5/site-packages/wtforms/form.py", line 278, in __init__
  File "/home/hadoop/development_projects/python/flask_microblog/virtenv/lib/python3.5/site-packages/wtforms/form.py", line 132, in process
  File "/home/hadoop/development_projects/python/flask_microblog/virtenv/lib/python3.5/site-packages/wtforms/csrf/core.py", line 43, in process
  File "/home/hadoop/development_projects/python/flask_microblog/virtenv/lib/python3.5/site-packages/flask_wtf/csrf.py", line 134, in generate_csrf_token
  File "/home/hadoop/development_projects/python/flask_microblog/virtenv/lib/python3.5/site-packages/flask_wtf/csrf.py", line 47, in generate_csrf
  File "/home/hadoop/development_projects/python/flask_microblog/virtenv/lib/python3.5/site-packages/itsdangerous.py", line 565, in dumps
  File "/home/hadoop/development_projects/python/flask_microblog/virtenv/lib/python3.5/site-packages/itsdangerous.py", line 847, in dump_payload
  File "/home/hadoop/development_projects/python/flask_microblog/virtenv/lib/python3.5/site-packages/itsdangerous.py", line 550, in dump_payload
  File "/home/hadoop/development_projects/python/flask_microblog/virtenv/lib/python3.5/site-packages/itsdangerous.py", line 51, in dumps
  File "/usr/lib/python3.5/json/__init__.py", line 237, in dumps
    **kw).encode(obj)
  File "/usr/lib/python3.5/json/encoder.py", line 198, in encode
    chunks = self.iterencode(o, _one_shot=True)
  File "/usr/lib/python3.5/json/encoder.py", line 256, in iterencode
    return _iterencode(o, 0)
  File "/usr/lib/python3.5/json/encoder.py", line 179, in default
    raise TypeError(repr(o) + " is not JSON serializable")
TypeError: b'f8ad3dfd41392fda368b3f38eb59e461791e33e7' is not JSON serializable
2018-02-17 00:54:23,378 ERROR: Exception on /login [GET] 
 		 [in /home/hadoop/development_projects/python/flask_microblog/virtenv/lib/python3.5/site-packages/flask/app.py:1560]
Traceback (most recent call last):
  File "/home/hadoop/development_projects/python/flask_microblog/virtenv/lib/python3.5/site-packages/flask/app.py", line 1982, in wsgi_app
  File "/home/hadoop/development_projects/python/flask_microblog/virtenv/lib/python3.5/site-packages/flask/app.py", line 1614, in full_dispatch_request
  File "/home/hadoop/development_projects/python/flask_microblog/virtenv/lib/python3.5/site-packages/flask/app.py", line 1517, in handle_user_exception
  File "/home/hadoop/development_projects/python/flask_microblog/virtenv/lib/python3.5/site-packages/flask/_compat.py", line 33, in reraise
  File "/home/hadoop/development_projects/python/flask_microblog/virtenv/lib/python3.5/site-packages/flask/app.py", line 1612, in full_dispatch_request
  File "/home/hadoop/development_projects/python/flask_microblog/virtenv/lib/python3.5/site-packages/flask/app.py", line 1598, in dispatch_request
  File "/home/hadoop/development_projects/python/flask_microblog/app/routes.py", line 40, in login
    form_obj = LoginForm()
  File "/home/hadoop/development_projects/python/flask_microblog/virtenv/lib/python3.5/site-packages/wtforms/form.py", line 212, in __call__
  File "/home/hadoop/development_projects/python/flask_microblog/virtenv/lib/python3.5/site-packages/flask_wtf/form.py", line 88, in __init__
  File "/home/hadoop/development_projects/python/flask_microblog/virtenv/lib/python3.5/site-packages/wtforms/form.py", line 278, in __init__
  File "/home/hadoop/development_projects/python/flask_microblog/virtenv/lib/python3.5/site-packages/wtforms/form.py", line 132, in process
  File "/home/hadoop/development_projects/python/flask_microblog/virtenv/lib/python3.5/site-packages/wtforms/csrf/core.py", line 43, in process
  File "/home/hadoop/development_projects/python/flask_microblog/virtenv/lib/python3.5/site-packages/flask_wtf/csrf.py", line 134, in generate_csrf_token
  File "/home/hadoop/development_projects/python/flask_microblog/virtenv/lib/python3.5/site-packages/flask_wtf/csrf.py", line 47, in generate_csrf
  File "/home/hadoop/development_projects/python/flask_microblog/virtenv/lib/python3.5/site-packages/itsdangerous.py", line 565, in dumps
  File "/home/hadoop/development_projects/python/flask_microblog/virtenv/lib/python3.5/site-packages/itsdangerous.py", line 847, in dump_payload
  File "/home/hadoop/development_projects/python/flask_microblog/virtenv/lib/python3.5/site-packages/itsdangerous.py", line 550, in dump_payload
  File "/home/hadoop/development_projects/python/flask_microblog/virtenv/lib/python3.5/site-packages/itsdangerous.py", line 51, in dumps
  File "/usr/lib/python3.5/json/__init__.py", line 237, in dumps
    **kw).encode(obj)
  File "/usr/lib/python3.5/json/encoder.py", line 198, in encode
    chunks = self.iterencode(o, _one_shot=True)
  File "/usr/lib/python3.5/json/encoder.py", line 256, in iterencode
    return _iterencode(o, 0)
  File "/usr/lib/python3.5/json/encoder.py", line 179, in default
    raise TypeError(repr(o) + " is not JSON serializable")
TypeError: b'f8ad3dfd41392fda368b3f38eb59e461791e33e7' is not JSON serializable
